<?xml version="1.0" ?>
<!-- =================================================================================== -->
<!-- |    This document was autogenerated by xacro from src/ros2_robot_simulation/models/urdf/jetbot.urdf | -->
<!-- |    EDITING THIS FILE BY HAND IS NOT RECOMMENDED                                 | -->
<!-- =================================================================================== -->
<robot name="JetBot">
  <gazebo reference="left_wheel">
    <mu1>0.1</mu1>
    <mu2>0.1</mu2>
    <kp>500.0</kp>
    <kd>10.0</kd>
    <min_depth>0.001</min_depth>
    <max_vel>0.5</max_vel>
    <fdir1>1 0 0</fdir1>
  </gazebo>
  <gazebo reference="right_wheel">
    <mu1>0.1</mu1>
    <mu2>0.1</mu2>
    <kp>500.0</kp>
    <kd>10.0</kd>
    <min_depth>0.001</min_depth>
    <max_vel>0.5</max_vel>
    <fdir1>1 0 0</fdir1>
  </gazebo>
  <gazebo>
    <plugin filename="libgazebo_ros_diff_drive.so" name="diff_drive_controller">
      <command_topic>cmd_vel</command_topic>
      <odometry_topic>odom</odometry_topic>
      <odometry_frame>odom</odometry_frame>
      <odometry_source>encoder</odometry_source>
      <publish_odom_tf>true</publish_odom_tf>
      <robot_base_frame>base_footprint</robot_base_frame>
      <publish_wheel_tf>false</publish_wheel_tf>
      <publish_tf>true</publish_tf>
      <publish_wheel_joint_state>true</publish_wheel_joint_state>
      <legacy_mode>false</legacy_mode>
      <update_rate>30</update_rate>
      <left_joint>left_wheel_hinge</left_joint>
      <right_joint>right_wheel_hinge</right_joint>
      <wheel_separation>0.096</wheel_separation>
      <wheel_diameter>0.065</wheel_diameter>
      <wheel_acceleration>1</wheel_acceleration>
      <wheel_torque>1</wheel_torque>
      <ros_debug_level>na</ros_debug_level>
    </plugin>
  </gazebo>
  <gazebo reference="camera_link">
    <sensor name="camera" type="camera">
      <always_on>true</always_on>
      <visualize>true</visualize>
      <camera>
        <horizontal_fov>2.79253</horizontal_fov>
        <image>
          <width>640</width>
          <height>320</height>
          <format>R8G8B8</format>
        </image>
        <clip>
          <near>0.01</near>
          <far>1</far>
        </clip>
        <noise>
          <type>gaussian</type>
          <mean>0.0</mean>
          <stddev>0.01</stddev>
        </noise>
      </camera>
      <plugin filename="libgazebo_ros_camera.so" name="camera_controller">
        <always_on>true</always_on>
        <update_rate>30.0</update_rate>
        <camera_name>camera</camera_name>
        <frame_name>camera_link</frame_name>
        <ros>
          <remapping>camera/image_raw:=image</remapping>
        </ros>
        <hack_baseline>0.07</hack_baseline>
        <distortion_k1>0.0</distortion_k1>
        <distortion_k2>0.0</distortion_k2>
        <distortion_k3>0.0</distortion_k3>
        <distortion_t1>0.0</distortion_t1>
        <distortion_t2>0.0</distortion_t2>
      </plugin>
    </sensor>
  </gazebo>
  <link name="base_footprint"/>
  <link name="base_link">
    <visual name="visual">
      <origin rpy="1.57079 0 1.57079" xyz="0 0 0.043"/>
      <geometry>
        <mesh filename="package://meshes/JetBot-v3-Chassis.dae" scale="0.001 0.001 0.001"/>
      </geometry>
    </visual>
    <collision name="collision">
      <origin rpy="1.57079 0 1.57079" xyz="0 0 0.043"/>
      <geometry>
        <mesh filename="package://meshes/JetBot-v3-Chassis.dae" scale="0.001 0.001 0.001"/>
      </geometry>
    </collision>
    <inertial>
      <mass value="1.0"/>
      <origin rpy="0 0 0" xyz="0 0 0"/>
      <inertia ixx="1e-3" ixy="0" ixz="0" iyy="1e-3" iyz="0" izz="1e-3"/>
    </inertial>
  </link>
  <joint name="base_joint" type="fixed">
    <parent link="base_footprint"/>
    <child link="base_link"/>
    <origin rpy="0 0 0" xyz="0.0 0.0 0.010"/>
  </joint>
  <link name="left_wheel">
    <visual name="visual">
      <origin rpy="0  0  0" xyz="0  0  0"/>
      <geometry>
        <mesh filename="package://meshes/JetBot-v3-Wheel.stl" scale="0.001 0.001 0.001"/>
      </geometry>
    </visual>
    <collision name="collision">
      <origin rpy="0  1.570796327 0" xyz="0 0 0"/>
      <geometry>
        <cylinder length="0.008" radius="0.030"/>
      </geometry>
    </collision>
    <inertial>
      <mass value="0.1"/>
      <origin rpy="0 0 0" xyz="0 0 0"/>
      <inertia ixx="1e-3" ixy="0" ixz="0" iyy="1e-3" iyz="0" izz="1e-3"/>
    </inertial>
  </link>
  <joint name="left_wheel_hinge" type="continuous">
    <parent link="base_link"/>
    <child link="left_wheel"/>
    <origin rpy="0 0 1.57079" xyz="0.03 0.05125 0.03"/>
    <axis xyz="1 0 0"/>
  </joint>
  <transmission name="tran_jetbot_left_wheel_hinge">
    <type>transmission_interface/SimpleTransmission</type>
    <joint name="left_wheel_hinge">
      <hardware_interface>hardware_interface/VelocityJointInterface</hardware_interface>
    </joint>
    <actuator name="motor_left_wheel">
      <mechanical_reduction>1</mechanical_reduction>
      <hardware_interface>VelocityJointInterface</hardware_interface>
    </actuator>
  </transmission>
  <link name="right_wheel">
    <visual name="visual">
      <origin rpy="0  0  0" xyz="0  0  0"/>
      <geometry>
        <mesh filename="package://meshes/JetBot-v3-Wheel.stl" scale="0.001 0.001 0.001"/>
      </geometry>
    </visual>
    <collision name="collision">
      <origin rpy="0  1.570796327 0" xyz="0 0 0"/>
      <geometry>
        <cylinder length="0.008" radius="0.030"/>
      </geometry>
    </collision>
    <inertial>
      <mass value="0.1"/>
      <origin rpy="0 0 0" xyz="0 0 0"/>
      <inertia ixx="1e-3" ixy="0" ixz="0" iyy="1e-3" iyz="0" izz="1e-3"/>
    </inertial>
  </link>
  <joint name="right_wheel_hinge" type="continuous">
    <parent link="base_link"/>
    <child link="right_wheel"/>
    <origin rpy="0 0 1.57079" xyz="0.03 -0.0595 0.03"/>
    <axis xyz="1 0 0"/>
  </joint>
  <transmission name="tran_jetbot_right_wheel_hinge">
    <type>transmission_interface/SimpleTransmission</type>
    <joint name="left_wheel_hinge">
      <hardware_interface>hardware_interface/VelocityJointInterface</hardware_interface>
    </joint>
    <actuator name="motor_left_wheel">
      <mechanical_reduction>1</mechanical_reduction>
      <hardware_interface>VelocityJointInterface</hardware_interface>
    </actuator>
  </transmission>
  <link name="camera_link">
    <visual name="visual">
      <origin rpy="0 0 0" xyz="0 0 0"/>
      <geometry>
        <box size="0.001 0.001 0.001"/>
      </geometry>
    </visual>
    <inertial>
      <mass value="0.01"/>
      <origin rpy="0 0 0" xyz="0 0 0"/>
      <inertia ixx="0" ixy="0" ixz="0" iyy="0" iyz="0" izz="0"/>
    </inertial>
  </link>
  <joint name="camera_joint" type="fixed">
    <parent link="base_link"/>
    <child link="camera_link"/>
    <origin rpy="0 0.25 0" xyz="0.065 0 0.0857"/>
    <axis xyz="0.96891 0 0.2474"/>
  </joint>
</robot>
